<?xml version="1.0" encoding="utf-8"?>
<!-- =================================================================================== -->
<!-- |    This document was autogenerated by xacro from V5.xacro                       | -->
<!-- |    EDITING THIS FILE BY HAND IS NOT RECOMMENDED                                 | -->
<!-- =================================================================================== -->
<robot name="V5">
  <material name="silver">
    <color rgba="0.700 0.700 0.700 1.000"/>
  </material>
  <transmission name="Rev5_tran">
    <type>transmission_interface/SimpleTransmission</type>
    <joint name="Rev5">
      <hardwareInterface>hardware_interface/EffortJointInterface</hardwareInterface>
    </joint>
    <actuator name="Rev5_actr">
      <hardwareInterface>hardware_interface/EffortJointInterface</hardwareInterface>
      <mechanicalReduction>1</mechanicalReduction>
    </actuator>
  </transmission>
  <transmission name="Rev6_tran">
    <type>transmission_interface/SimpleTransmission</type>
    <joint name="Rev6">
      <hardwareInterface>hardware_interface/EffortJointInterface</hardwareInterface>
    </joint>
    <actuator name="Rev6_actr">
      <hardwareInterface>hardware_interface/EffortJointInterface</hardwareInterface>
      <mechanicalReduction>1</mechanicalReduction>
    </actuator>
  </transmission>
  <transmission name="Rev7_tran">
    <type>transmission_interface/SimpleTransmission</type>
    <joint name="Rev7">
      <hardwareInterface>hardware_interface/EffortJointInterface</hardwareInterface>
    </joint>
    <actuator name="Rev7_actr">
      <hardwareInterface>hardware_interface/EffortJointInterface</hardwareInterface>
      <mechanicalReduction>1</mechanicalReduction>
    </actuator>
  </transmission>
  <transmission name="Rev8_tran">
    <type>transmission_interface/SimpleTransmission</type>
    <joint name="Rev8">
      <hardwareInterface>hardware_interface/EffortJointInterface</hardwareInterface>
    </joint>
    <actuator name="Rev8_actr">
      <hardwareInterface>hardware_interface/EffortJointInterface</hardwareInterface>
      <mechanicalReduction>1</mechanicalReduction>
    </actuator>
  </transmission>
  <gazebo>
    <plugin filename="libgazebo_ros_control.so" name="control"/>
  </gazebo>
  <gazebo reference="base_link">
    <material>Gazebo/Silver</material>
    <mu1>0.2</mu1>
    <mu2>0.2</mu2>
    <selfCollide>true</selfCollide>
    <gravity>true</gravity>
  </gazebo>
  <gazebo reference="link_3_1">
    <material>Gazebo/Silver</material>
    <mu1>0.2</mu1>
    <mu2>0.2</mu2>
    <selfCollide>true</selfCollide>
  </gazebo>
  <gazebo reference="link_2_1">
    <material>Gazebo/Silver</material>
    <mu1>0.2</mu1>
    <mu2>0.2</mu2>
    <selfCollide>true</selfCollide>
  </gazebo>
  <gazebo reference="link_1_1">
    <material>Gazebo/Silver</material>
    <mu1>0.2</mu1>
    <mu2>0.2</mu2>
    <selfCollide>true</selfCollide>
  </gazebo>
  <gazebo reference="link_0_1">
    <material>Gazebo/Silver</material>
    <mu1>0.2</mu1>
    <mu2>0.2</mu2>
    <selfCollide>true</selfCollide>
  </gazebo>
  <link name="base_link">
    <inertial>
      <origin rpy="0 0 0" xyz="0.0030690000529868112 -0.004930753908953767 0.0060954147991827655"/>
      <mass value="0.001017166589049506"/>
      <inertia ixx="0.0" ixy="0.0" ixz="0.0" iyy="0.0" iyz="0.0" izz="0.0"/>
    </inertial>
    <visual>
      <origin rpy="0 0 0" xyz="0 0 0"/>
      <geometry>
        <mesh filename="package://V5_description/meshes/base_link.stl" scale="0.001 0.001 0.001"/>
      </geometry>
      <material name="silver"/>
    </visual>
    <collision>
      <origin rpy="0 0 0" xyz="0 0 0"/>
      <geometry>
        <mesh filename="package://V5_description/meshes/base_link.stl" scale="0.001 0.001 0.001"/>
      </geometry>
    </collision>
  </link>
  <link name="link_3_1">
    <inertial>
      <origin rpy="0 0 0" xyz="-0.005152868471693287 0.02481010722854876 0.0018574172697317093"/>
      <mass value="0.011902447961491562"/>
      <inertia ixx="1.1e-05" ixy="-0.0" ixz="0.0" iyy="1e-06" iyz="-1e-06" izz="1e-05"/>
    </inertial>
    <visual>
      <origin rpy="0 0 0" xyz="-0.005069 -0.285069 -0.031743"/>
      <geometry>
        <mesh filename="package://V5_description/meshes/link_3_1.stl" scale="0.001 0.001 0.001"/>
      </geometry>
      <material name="silver"/>
    </visual>
    <collision>
      <origin rpy="0 0 0" xyz="-0.005069 -0.285069 -0.031743"/>
      <geometry>
        <mesh filename="package://V5_description/meshes/link_3_1.stl" scale="0.001 0.001 0.001"/>
      </geometry>
    </collision>
  </link>
  <link name="link_2_1">
    <inertial>
      <origin rpy="0 0 0" xyz="0.0009055416474958236 0.049999413752218724 2.1327025657297272e-07"/>
      <mass value="0.10132228949775199"/>
      <inertia ixx="0.000184" ixy="-0.0" ixz="-0.0" iyy="4e-06" iyz="0.0" izz="0.000184"/>
    </inertial>
    <visual>
      <origin rpy="0 0 0" xyz="-0.005069 -0.185069 -0.031743"/>
      <geometry>
        <mesh filename="package://V5_description/meshes/link_2_1.stl" scale="0.001 0.001 0.001"/>
      </geometry>
      <material name="silver"/>
    </visual>
    <collision>
      <origin rpy="0 0 0" xyz="-0.005069 -0.185069 -0.031743"/>
      <geometry>
        <mesh filename="package://V5_description/meshes/link_2_1.stl" scale="0.001 0.001 0.001"/>
      </geometry>
    </collision>
  </link>
  <link name="link_1_1">
    <inertial>
      <origin rpy="0 0 0" xyz="-0.004689560010774196 0.07499986334155206 0.0010242857380551376"/>
      <mass value="0.026203534667712382"/>
      <inertia ixx="7.9e-05" ixy="0.0" ixz="-0.0" iyy="2e-06" iyz="0.0" izz="7.8e-05"/>
    </inertial>
    <visual>
      <origin rpy="0 0 0" xyz="-0.005069 -0.035069 -0.031743"/>
      <geometry>
        <mesh filename="package://V5_description/meshes/link_1_1.stl" scale="0.001 0.001 0.001"/>
      </geometry>
      <material name="silver"/>
    </visual>
    <collision>
      <origin rpy="0 0 0" xyz="-0.005069 -0.035069 -0.031743"/>
      <geometry>
        <mesh filename="package://V5_description/meshes/link_1_1.stl" scale="0.001 0.001 0.001"/>
      </geometry>
    </collision>
  </link>
  <link name="link_0_1">
    <inertial>
      <origin rpy="0 0 0" xyz="0.0038425748097726006 0.020806219418995853 0.015441576217583838"/>
      <mass value="0.016056852755794385"/>
      <inertia ixx="9e-06" ixy="-1e-06" ixz="-0.0" iyy="3e-06" iyz="-3e-06" izz="8e-06"/>
    </inertial>
    <visual>
      <origin rpy="0 0 0" xyz="-0.003069 0.004931 -0.005243"/>
      <geometry>
        <mesh filename="package://V5_description/meshes/link_0_1.stl" scale="0.001 0.001 0.001"/>
      </geometry>
      <material name="silver"/>
    </visual>
    <collision>
      <origin rpy="0 0 0" xyz="-0.003069 0.004931 -0.005243"/>
      <geometry>
        <mesh filename="package://V5_description/meshes/link_0_1.stl" scale="0.001 0.001 0.001"/>
      </geometry>
    </collision>
  </link>
  <link name="tcp_link">
    <inertial>       <origin rpy="0 0 0" xyz="0 0 0"/>
      <mass value="0.001"/> <!-- Minimal mass for visualization -->
      <inertia ixx="0.0001" ixy="0.0" ixz="0.0" iyy="0.0001" iyz="0.0" izz="0.0001"/>
    </inertial>
    <visual>
      <origin rpy="0 0 0" xyz="0 0 0"/>
      <geometry>
        <sphere radius="0.00"/> <!-- Small sphere representing the TCP -->
      </geometry>
      <material name="red">
        <color rgba="1.0 0.0 0.0 1.0"/> <!-- Red color for visibility -->
      </material>
    </visual>
    <collision>
      <origin rpy="0 0 0" xyz="0 0 0"/>
      <geometry>
        <sphere radius="0.0"/>
      </geometry>
    </collision>
  </link>
  <joint name="tcp_joint" type="fixed">
    <origin rpy="0 0 0" xyz="-0.00475 0.00225 0.0038971"/>
    <parent link="evd_link"/>
    <child link="tcp_link"/>
  </joint>
  <link name="evd_link">
    <inertial>       <origin rpy="0 0 0" xyz="0 0 0"/>
      <mass value="0.001"/> <!-- Minimal mass for visualization -->
      <inertia ixx="0.0001" ixy="0.0" ixz="0.0" iyy="0.0001" iyz="0.0" izz="0.0001"/>
    </inertial>
    <visual>
      <origin rpy="0 0 0" xyz="0 0 0"/>
      <geometry>
        <sphere radius="0.00"/> <!-- Small sphere representing the EVD Link (effector) -->
      </geometry>
      <material name="red">
        <color rgba="1.0 0.0 0.0 1.0"/> <!-- Red color for visibility -->
      </material>
    </visual>
    <collision>
      <origin rpy="0 0 0" xyz="0 0 0"/>
      <geometry>
        <sphere radius="0.0"/>
      </geometry>
    </collision>
  </link>
  <joint name="evd_joint" type="fixed">
    <origin rpy="0 0 0" xyz="-0.00175 0.079937 0.021542"/>
    <parent link="link_3_1"/>
    <child link="evd_link"/>
  </joint>
  <joint name="Rev5" type="continuous">
    <origin rpy="0 0 0" xyz="0.0 0.1 0.0"/>
    <parent link="link_2_1"/>
    <child link="link_3_1"/>
    <axis xyz="-1.0 0.0 -0.0"/>
  </joint>
  <joint name="Rev6" type="continuous">
    <origin rpy="0 0 0" xyz="0.0 0.15 0.0"/>
    <parent link="link_1_1"/>
    <child link="link_2_1"/>
    <axis xyz="-1.0 0.0 -0.0"/>
  </joint>
  <joint name="Rev7" type="continuous">
    <origin rpy="0 0 0" xyz="0.002 0.04 0.0265"/>
    <parent link="link_0_1"/>
    <child link="link_1_1"/>
    <axis xyz="-1.0 0.0 -0.0"/>
  </joint>
  <joint name="Rev8" type="continuous">
    <origin rpy="0 0 0" xyz="0.003069 -0.004931 0.005243"/>
    <parent link="base_link"/>
    <child link="link_0_1"/>
    <axis xyz="-0.0 0.0 1.0"/>
  </joint>
  <klampt package_root="../.." />
</robot>
